Workbook

Sheet Key
A1: Participant ID | B1: Continuous
A2: Gender | B2: Categorical | C2: Male | D2: 0
C3: Female | D3: 1
C4: Other | D4: 2
C5: Prefer not to answer | D5: 3
A6: Clinical Position | B6: Categorical | C6: Resident Physician | D6: 0
C7: Attending Physician | D7: 1
C8: Physician Assistant | D8: 2
C9: Nurse Practitioner | D9: 3
C10: Certified Nurse Midwife | D10: 4
C11: Registered Nurse | D11: 5
C12: Other | D12: 6
A13: NICU | B13: Categorical | C13: No | D13: 0
C14: Yes | D14: 1
A15: Well baby nursery | B15: Categorical | C15: No | D15: 0
C16: Yes | D16: 1
A17: Labor and Delivery | B17: Categorical | C17: No | D17: 0
C18: Yes | D18: 1
A19: Women's health clinic | B19: Categorical | C19: No | D19: 0
C20: Yes | D20: 1
A21: Pediatric Clinic | B21: Categorical | C21: No | D21: 0
C22: Yes | D22: 1
A23: Years in Clinical Practice | B23: Continuous
A24: Pre Simulation Knowledge: Question 5 | B24: Categorical | C24: Incorrect | D24: 0
C25: Correct | D25: 1
A26: Pre Simulation Knowledge: Question 6 | B26: Categorical | C26: Incorrect | D26: 0
C27: Correct | D27: 1
A28: Pre Simulation Knowledge: Question 7 | B28: Categorical | C28: Incorrect | D28: 0
C29: Correct | D29: 1
A30: Pre Simulation Knowledge: Question 8 | B30: Categorical | C30: Incorrect | D30: 0
C31: Correct | D31: 1
A32: Pre Simulation Knowledge: Question 9 | B32: Categorical | C32: Incorrect | D32: 0
C33: Correct | D33: 1
A34: Pre Simulation Knowledge: Question 10 | B34: Categorical | C34: No | D34: 0
C35: Yes | D35: 1
A36: Pre Simulation Comfort: 11a | B36: Categorical | C36: Not at all comfortable | D36: 1
C37: Slightly comfortable | D37: 2
C38: Moderately comfortable | D38: 3
C39: Very comfortable | D39: 4
C40: Extremely Comfortable | D40: 5
...

Sheet Data
A1: Participant ID | B1: Gender | C1: Clinical Position | D1: NICU | E1: Well baby nursery | F1: Labor and Delivery | G1: Women's health clinic | H1: Pediatric Clinic | I1: Years in Practice | J1: Pre Simulation Knowledge: Question 5 | K1: Pre Simulation Knowledge: Question 6 | L1: Pre Simulation Knowledge: Question 7 | M1: Pre Simulation Knowledge: Question 8 | N1: Pre Simulation Knowledge: Question 9 | O1: Pre Simulation Knowledge: Question 10 | P1: Pre Simulation Comfort: 11a | Q1: Pre Simulation Comfort: 11b | R1: Pre Simulation Comfort: 11c | S1: Pre Simulation Comfort: 11d | T1: Pre Simulation Attitude: 12a | U1: Pre Simulation Attitude: 12b | V1: Pre Simulation Attitude: 12c | W1: Pre Simulation Attitude: 12d | X1: Pre Simulation Attitude: 12e | Y1: Post Simulation Knowledge: Question 5 | Z1: Post Simulation Knowledge: Question 6 | AA1: Post Simulation Knowledge: Question 7 | AB1: Post Simulation Knowledge: Question 8 | AC1: Post Simulation Knowledge: Question 9 | AD1: Post Simulation Comfort: 10a | AE1: Post Simulation Comfort: 10b | AF1: Post Simulation Comfort: 10c | AG1: Post Simulation Comfort: 10d | AH1: Post Simulation Attitude: 11a | AI1: Post Simulation Attitude: 11b | AJ1: Post Simulation Attitude: 11c | AK1: Post Simulation Attitude: 11d | AL1: Post Simulation Attitude: 11e
A2: FI465 | B2: 0 | C2: 0 | D2: 1 | E2: 1 | F2: 0 | G2: 0 | H2: 1 | I2: 3 | J2: 1 | K2: 1 | L2: 1 | M2: 1 | N2: 1 | O2: 0 | P2: 1 | Q2: 1 | R2: 1 | S2: 1 | T2: 3 | U2: 4 | V2: 4 | W2: 3 | X2: 1 | Y2: 1 | Z2: 1 | AA2: 1 | AB2: 1 | AC2: 1 | AD2: 5 | AE2: 5 | AF2: 4 | AG2: 3 | AH2: 4 | AI2: 5 | AJ2: 2 | AK2: 2 | AL2: 1
A3: EL855 | B3: 1 | C3: 0 | D3: 1 | E3: 1 | F3: 1 | G3: 0 | H3: 1 | I3: 1.5 | J3: 1 | K3: 1 | L3: 0 | M3: 1 | N3: 1 | O3: 0 | P3: 1 | Q3: 1 | R3: 1 | S3: 1 | T3: 3 | U3: 4 | V3: 3 | W3: 2 | X3: 1 | Y3: 1 | Z3: 1 | AA3: 1 | AB3: 1 | AC3: 1 | AD3: 3 | AE3: 4 | AF3: 2 | AG3: 2 | AH3: 2 | AI3: 4 | AJ3: 2 | AK3: 2 | AL3: 1
A4: WE967 | B4: 1 | C4: 0 | D4: 1 | E4: 1 | F4: 0 | G4: 0 | H4: 1 | I4: 2.5 | J4: 1 | K4: 1 | L4: 0 | M4: 1 | N4: 1 | O4: 0 | P4: 1 | Q4: 1 | R4: 2 | S4: 1 | T4: 4 | U4: 5 | V4: 2 | W4: 2 | X4: 1 | Y4: 1 | Z4: 1 | AA4: 1 | AB4: 1 | AC4: 1 | AD4: 4 | AE4: 4 | AF4: 4 | AG4: 3 | AH4: 1 | AI4: 5 | AJ4: 2 | AK4: 2 | AL4: 1
A5: PE127 | B5: 1 | C5: 0 | D5: 1 | E5: 1 | F5: 0 | G5: 0 | H5: 1 | I5: 3 | J5: 1 | K5: 1 | L5: 1 | M5: 1 | N5: 1 | O5: 0 | P5: 1 | Q5: 1 | R5: 1 | S5: 1 | T5: 2 | U5: 5 | V5: 2 | W5: 2 | X5: 1 | Y5: 1 | Z5: 1 | AA5: 1 | AB5: 1 | AC5: 1 | AD5: 4 | AE5: 4 | AF5: 4 | AG5: 1 | AH5: 2 | AI5: 5 | AJ5: 1 | AK5: 1 | AL5: 1
A6: NO224 | B6: 1 | C6: 0 | D6: 1 | E6: 1 | F6: 0 | G6: 0 | H6: 1 | I6: 1 | J6: 1 | K6: 1 | L6: 0 | M6: 1 | N6: 1 | O6: 0 | P6: 1 | Q6: 1 | R6: 1 | S6: 1 | T6: 2 | U6: 3 | V6: 3 | W6: 3 | X6: 3 | Y6: 1 | Z6: 1 | AA6: 0 | AB6: 1 | AC6: 1 | AD6: 3 | AE6: 4 | AF6: 4 | AG6: 4 | AH6: 1 | AI6: 3 | AJ6: 2 | AK6: 1 | AL6: 1
A7: TS007 | B7: 1 | C7: 0 | D7: 1 | E7: 1 | F7: 0 | G7: 0 | H7: 0 | I7: 5 | J7: 1 | K7: 0 | L7: 0 | M7: 1 | N7: 1 | O7: 0 | P7: 3 | Q7: 1 | R7: 3 | S7: 1 | T7: 3 | U7: 4 | V7: 2 | W7: 2 | X7: 2 | Y7: 1 | Z7: 1 | AA7: 0 | AB7: 1 | AC7: 1 | AD7: 4 | AE7: 4 | AF7: 4 | AG7: 4 | AH7: 2 | AI7: 2 | AJ7: 2 | AK7: 2 | AL7: 1
A8: WO902 | B8: 1 | C8: 0 | D8: 1 | E8: 1 | F8: 0 | G8: 0 | H8: 1 | I8: 2 | J8: 0 | K8: 1 | L8: 0 | M8: 1 | N8: 1 | O8: 0 | P8: 2 | Q8: 1 | R8: 2 | S8: 2 | T8: 2 | U8: 5 | V8: 1 | W8: 1 | X8: 1 | Y8: 1 | Z8: 1 | AA8: 1 | AB8: 1 | AC8: 1 | AD8: 4 | AE8: 4 | AF8: 4 | AG8: 4 | AH8: 2 | AI8: 5 | AJ8: 1 | AK8: 1 | AL8: 1
A9: OA186 | B9: 1 | C9: 0 | D9: 1 | E9: 1 | F9: 0 | G9: 0 | H9: 1 | I9: 5 | J9: 1 | K9: 0 | L9: 1 | M9: 1 | N9: 1 | O9: 0 | P9: 3 | Q9: 2 | R9: 3 | S9: 4 | T9: 3 | U9: 4 | V9: 2 | W9: 3 | X9: 1 | Y9: 1 | Z9: 1 | AA9: 1 | AB9: 1 | AC9: 1 | AD9: 4 | AE9: 3 | AF9: 4 | AG9: 4
A10: ST512 | B10: 0 | C10: 0 | D10: 1 | E10: 1 | F10: 0 | G10: 0 | H10: 1 | I10: 2 | J10: 1 | K10: 1 | L10: 0 | M10: 1 | N10: 1 | O10: 0 | P10: 3 | Q10: 1 | R10: 3 | S10: 1 | T10: 3 | U10: 4 | V10: 3 | W10: 4 | X10: 2 | Y10: 1 | Z10: 1 | AA10: 1 | AB10: 1 | AC10: 1 | AD10: 4 | AE10: 4 | AF10: 4 | AG10: 2 | AH10: 3 | AI10: 5 | AJ10: 2 | AK10: 3 | AL10: 1
A11: MA833 | B11: 1 | C11: 0 | D11: 1 | E11: 1 | F11: 0 | G11: 0 | H11: 1 | I11: 1 | J11: 1 | K11: 1 | L11: 0 | M11: 1 | N11: 0 | O11: 0 | P11: 1 | Q11: 1 | R11: 1 | S11: 1 | T11: 3 | U11: 4 | V11: 2 | W11: 3 | X11: 2 | Y11: 1 | Z11: 1 | AA11: 1 | AB11: 1 | AC11: 1 | AD11: 3 | AE11: 3 | AF11: 3 | AG11: 3 | AH11: 2 | AI11: 4 | AJ11: 2 | AK11: 2 | AL11: 2
A12: MA730 | B12: 0 | C12: 0 | D12: 1 | E12: 1 | F12: 0 | G12: 0 | H12: 1 | I12: 7 | J12: 1 | K12: 1 | L12: 0 | M12: 1 | N12: 1 | O12: 0 | P12: 1 | Q12: 1 | R12: 1 | S12: 1 | T12: 1 | U12: 5 | V12: 4 | W12: 4 | X12: 1 | Y12: 1 | Z12: 1 | AA12: 1 | AB12: 1 | AC12: 1 | AD12: 4 | AE12: 4 | AF12: 4 | AG12: 4 | AH12: 1 | AI12: 5 | AJ12: 1 | AK12: 1 | AL12: 1
A13: NA896 | B13: 1 | C13: 0 | D13: 1 | E13: 1 | F13: 1 | G13: 0 | H13: 1 | I13: 1.5 | J13: 1 | K13: 1 | L13: 0 | M13: 1 | N13: 1 | O13: 0 | T13: 4 | U13: 5 | V13: 1 | W13: 2 | X13: 1 | Y13: 1 | Z13: 1 | AA13: 0 | AB13: 1 | AC13: 1 | AD13: 4 | AE13: 4 | AF13: 4 | AG13: 4 | AH13: 3 | AI13: 5 | AJ13: 1 | AK13: 1 | AL13: 1
A14: LE971 | B14: 0 | C14: 0 | D14: 1 | E14: 0 | F14: 0 | G14: 0 | H14: 0 | I14: 0.9 | J14: 1 | K14: 1 | L14: 0 | M14: 1 | N14: 1 | O14: 0 | P14: 1 | Q14: 1 | R14: 1 | S14: 1 | T14: 1 | U14: 4 | V14: 2 | W14: 1 | X14: 1 | Y14: 1 | Z14: 1 | AA14: 1 | AB14: 1 | AC14: 1 | AD14: 3 | AE14: 3 | AF14: 3 | AG14: 3
A15: AB022 | B15: 0 | C15: 0 | D15: 1 | E15: 1 | F15: 0 | G15: 0 | H15: 1 | I15: 1 | J15: 1 | K15: 1 | L15: 0 | M15: 0 | N15: 1 | O15: 0 | T15: 3 | U15: 4 | V15: 4 | W15: 3 | X15: 2 | Y15: 1 | Z15: 1 | AA15: 0 | AB15: 1 | AC15: 0 | AD15: 3 | AE15: 4 | AF15: 4 | AG15: 3 | AH15: 4 | AI15: 5 | AJ15: 4 | AK15: 5 | AL15: 4
A16: YZ448 | B16: 0 | C16: 0 | D16: 1 | E16: 1 | F16: 0 | G16: 0 | H16: 1 | I16: 1 | J16: 1 | K16: 1 | L16: 0 | M16: 0 | N16: 1 | O16: 0 | P16: 3 | Q16: 3 | R16: 2 | S16: 3 | T16: 3 | U16: 4 | V16: 4 | W16: 3 | X16: 2 | Y16: 1 | Z16: 0 | AA16: 0 | AB16: 1 | AC16: 1 | AD16: 4 | AE16: 4 | AF16: 5 | AG16: 4 | AH16: 4 | AI16: 5 | AJ16: 4 | AK16: 5 | AL16: 3
A17: SA261 | B17: 1 | C17: 0 | D17: 1 | E17: 1 | F17: 0 | G17: 0 | H17: 1 | I17: 2.5 | J17: 1 | K17: 1 | L17: 0 | M17: 1 | N17: 1 | O17: 0 | P17: 2 | Q17: 1 | R17: 3 | S17: 2 | T17: 3 | U17: 4 | V17: 3 | W17: 3 | X17: 2 | Y17: 1 | Z17: 1 | AA17: 0 | AB17: 1 | AC17: 1 | AD17: 4 | AE17: 4 | AF17: 5 | AG17: 5 | AH17: 1 | AI17: 5 | AJ17: 2 | AK17: 1 | AL17: 1
A18: NA062 | B18: 1 | C18: 0 | D18: 1 | E18: 1 | F18: 0 | G18: 0 | H18: 1 | I18: 1 | J18: 1 | K18: 1 | L18: 0 | M18: 1 | N18: 1 | O18: 0 | P18: 2 | Q18: 1 | R18: 2 | S18: 2 | T18: 2 | U18: 4 | V18: 2 | W18: 2 | X18: 1 | Y18: 1 | Z18: 1 | AA18: 1 | AB18: 1 | AC18: 1 | AD18: 4 | AE18: 5 | AF18: 4 | AG18: 4 | AH18: 1 | AI18: 5 | AJ18: 1 | AK18: 1 | AL18: 1
A19: AE417 | B19: 1 | C19: 0 | D19: 1 | E19: 1 | F19: 0 | G19: 0 | H19: 1 | I19: 1 | J19: 1 | K19: 1 | L19: 0 | M19: 1 | N19: 1 | O19: 0 | P19: 1 | Q19: 1 | R19: 1 | S19: 1 | T19: 4 | U19: 4 | V19: 2 | W19: 1 | X19: 1 | Y19: 0 | Z19: 1 | AA19: 1 | AB19: 1 | AC19: 1 | AD19: 5 | AE19: 5 | AF19: 4 | AG19: 4 | AH19: 1 | AI19: 5 | AJ19: 1 | AK19: 1 | AL19: 1
A20: GL782 | B20: 1 | C20: 6 | D20: 1 | E20: 0 | F20: 1 | G20: 1 | H20: 1 | I20: 0 | J20: 1 | K20: 1 | L20: 0 | M20: 1 | N20: 1 | O20: 0 | P20: 1 | Q20: 1 | R20: 1 | S20: 1 | T20: 4 | U20: 4 | V20: 2 | W20: 3 | X20: 1 | Y20: 1 | Z20: 1 | AA20: 1 | AB20: 1 | AC20: 1 | AD20: 3 | AE20: 3 | AF20: 3 | AG20: 2 | AH20: 3 | AI20: 5 | AJ20: 1 | AK20: 2 | AL20: 1
A21: LI492 | B21: 1 | C21: 0 | D21: 1 | E21: 1 | F21: 0 | G21: 0 | H21: 1 | I21: 3 | J21: 1 | K21: 0 | L21: 1 | M21: 1 | N21: 1 | O21: 0 | P21: 3 | Q21: 1 | R21: 3 | S21: 2 | T21: 2 | U21: 5 | V21: 2 | W21: 1 | X21: 1 | Y21: 1 | Z21: 1 | AA21: 1 | AB21: 1 | AC21: 1 | AD21: 4 | AE21: 4 | AF21: 4 | AG21: 4 | AH21: 2 | AI21: 5 | AJ21: 2 | AK21: 1 | AL21: 1
A22: AB047 | B22: 1 | C22: 0 | D22: 1 | E22: 1 | F22: 0 | G22: 0 | H22: 1 | I22: 0.75 | J22: 1 | K22: 1 | L22: 0 | M22: 1 | N22: 1 | O22: 0 | P22: 1 | Q22: 1 | R22: 1 | S22: 2 | T22: 2 | U22: 4 | V22: 2 | W22: 3 | X22: 2 | Y22: 1 | Z22: 1 | AA22: 0 | AB22: 1 | AC22: 1 | AD22: 3 | AE22: 3 | AF22: 3 | AG22: 3 | AH22: 1 | AI22: 5 | AJ22: 1 | AK22: 3 | AL22: 1
A23: XX998 | B23: 1 | C23: 0 | D23: 1 | E23: 1 | F23: 0 | G23: 0 | H23: 1 | I23: 2 | J23: 0 | K23: 1 | L23: 0 | M23: 1 | N23: 1 | O23: 0 | P23: 1 | Q23: 1 | R23: 2 | S23: 1 | T23: 4 | U23: 3 | V23: 2 | W23: 4 | X23: 2
A24: XX999 | B24: 1 | C24: 0 | D24: 1 | E24: 1 | F24: 0 | G24: 0 | H24: 1 | I24: 3 | J24: 1 | K24: 1 | L24: 0 | M24: 1 | N24: 1 | O24: 0 | P24: 1 | Q24: 1 | R24: 1 | S24: 1 | T24: 5 | U24: 5 | V24: 1 | W24: 3 | X24: 4 | Y24: 0 | Z24: 1 | AA24: 1 | AB24: 1 | AC24: 1 | AD24: 5 | AE24: 5 | AF24: 5 | AG24: 5 | AH24: 1 | AI24: 5 | AJ24: 1 | AK24: 1 | AL24: 1

Sheet Analysis
A1: Gender
A2: Male | B2: =COUNTIF(Data!B2:B24,"0") -> 6
A3: Female | B3: =COUNTIF(Data!B2:B24,"1") -> 17
A5: Clinical Position
A6: Resident | B6: =COUNTIF(Data!C2:C24,"0") -> 22
A7: Other | B7: =COUNTIF(Data!C2:C24,"6") -> 1
A9: Clinical Responsibility
A10: NICU | B10: =COUNTIF(Data!D2:D24,"1") -> 23
A11: Well baby nursery | B11: =COUNTIF(Data!E2:E24,"1") -> 21
A12: Labor and Delivery | B12: =COUNTIF(Data!F2:F24,"1") -> 3
A13: Women's health clinic | B13: =COUNTIF(Data!G2:G24,"1") -> 1
A14: Pediatric clinic | B14: =COUNTIF(Data!H2:H24,"1") -> 21
A16: Years in practice | B16: =AVERAGE(Data!I2:I24) -> 2.2021739
A18: Pre Sim Question 5 | D18: Post Sim Question 5
A19: Correct | B19: =COUNTIF(Data!J2:J24,"1") -> 21 | D19: =COUNTIF(Data!Y2:Y24,"1") -> 20
A20: Incorrect | B20: =COUNTIF(Data!J2:J24,"0") -> 2 | D20: =COUNTIF(Data!Y2:Y24,"0") -> 2
A22: Pre Sim Question 6 | D22: Post Sim Question 6
A23: Correct | B23: =COUNTIF(Data!K2:K24,"1") -> 20 | D23: =COUNTIF(Data!Z2:Z24,"1") -> 21
A24: Incorrect | B24: =COUNTIF(Data!K2:K24,"0") -> 3 | D24: =COUNTIF(Data!Z2:Z24,"0") -> 1
A26: Pre Sim Question 7 | D26: Post Sim Question 7
A27: Correct | B27: =COUNTIF(Data!L2:L24,"1") -> 4 | D27: =COUNTIF(Data!AA2:AA24,"1") -> 15
A28: Incorrect | B28: =COUNTIF(Data!L2:L24,"0") -> 19 | D28: =COUNTIF(Data!AA2:AA24,"0") -> 7
A30: Pre Sim Question 8 | D30: Post Sim Question 8
A31: Correct | B31: =COUNTIF(Data!M2:M24,"1") -> 21 | D31: =COUNTIF(Data!AB2:AB24,"1") -> 22
A32: Incorrect | B32: =COUNTIF(Data!M2:M24,"0") -> 2 | D32: =COUNTIF(Data!AB2:AB24,"0") -> 0
A34: Pre Sim Question 9 | D34: Post Sim Question 9
A35: Correct | B35: =COUNTIF(Data!N2:N24,"1") -> 22 | D35: =COUNTIF(Data!AC2:AC24,"1") -> 21
A36: Incorrect | B36: =COUNTIF(Data!N2:N24,"0") -> 1 | D36: =COUNTIF(Data!AC2:AC24,"0") -> 1
A38: Pre Sim Question 10
A39: Yes | B39: =COUNTIF(Data!O2:O24,"1") -> 0
A40: No | B40: =COUNTIF(Data!O2:O24,"0") -> 23
A42: Pre Sim Comfort 11a | D42: Post Sim Comfort 10a
A43: 1 | B43: =COUNTIF(Data!P2:P24,"1") -> 13 | D43: =COUNTIF(Data!AD2:AD24,"1") -> 0
A44: 2 | B44: =COUNTIF(Data!P2:P24,"2") -> 3 | D44: =COUNTIF(Data!AD2:AD24,"2") -> 0
A45: 3 | B45: =COUNTIF(Data!P2:P24,"3") -> 5 | D45: =COUNTIF(Data!AD2:AD24,"3") -> 7
A46: 4 | B46: =COUNTIF(Data!P2:P24,"4") -> 0 | D46: =COUNTIF(Data!AD2:AD24,"4") -> 12
A47: 5 | B47: =COUNTIF(Data!P2:P24,"5") -> 0 | D47: =COUNTIF(Data!AD2:AD24,"5") -> 3
A49: Pre Sim Comfort 11b | D49: Post Sim Comfort 10b
A50: 1 | B50: =COUNTIF(Data!Q2:Q24,"1") -> 19 | D50: =COUNTIF(Data!AE2:AE24,"1") -> 0
A51: 2 | B51: =COUNTIF(Data!Q2:Q24,"2") -> 1 | D51: =COUNTIF(Data!AE2:AE24,"2") -> 0
...
